<?xml version="1.0" ?>
<sdf version='1.4'>
<world name="world">

<!-- <physics type="dart"> -->
    <!-- Ground Plane -->
<!-- 190613 Modified by issac  -->
<!-- damping should be zero! if not -> makes error  -->
    <include>
      <uri>model://sun</uri>
    </include>
<include>
      <uri>model://ground_plane</uri>
    </include>
<!--
<model name="gplane">
      <pose>0.000000 0.000000 0.000000 0 0 0</pose>
      <link name="plane">
        <pose>0.000000 0.000000 0.000000 0.000000 -0.000000 0.000000</pose>
        <collision name="plane">
          <pose>0.000000 0.000000 0.000000 0.000000 -0.000000 0.000000</pose>
          <geometry>
            <plane>
              <normal>0.000000 0.000000 1.00000</normal>
            </plane>
          </geometry>
          <surface>

           <friction>
              <ode>
                <mu>100.000000</mu>
                <mu2>100.000000</mu2>
              </ode>
            </friction>
          </surface>
        </collision>
      </link>
    </model> -->

  <model name='downscale'>
  <!-- <static>false</static> -->
  <pose>0 0 0 0 0 0</pose>


    <link name='base'>
      <pose>0 0 0 0 -0 0</pose>
      <inertial>
        <pose>0 0 0.25 0 -0 0</pose>
        <mass>50</mass> <!-- assumtion??  -->
        <inertia>
          <ixx>1</ixx>
          <ixy>0</ixy>
          <ixz>0</ixz>
          <iyy>1</iyy>
          <iyz>0</iyz>
          <izz>1</izz>
        </inertia>
      </inertial>

      <collision name='base_collision'>
        <pose>0 0 0 0 -0 0</pose>
        <geometry>
          <mesh>
            <scale>1 1 1</scale>
            <uri>/home/robotory/catkin_ws/src/downscale4/world/base.dae</uri>
          </mesh>
        </geometry>
      </collision>
      <visual name='base_visual'>
        <pose>0 0 0 0 -0 0</pose>
        <geometry>
          <mesh>
            <scale>1 1 1</scale>
            <uri>/home/robotory/catkin_ws/src/downscale4/world/base.dae</uri>
          </mesh>
        </geometry>
	<material>
          <script>
            <name>Gazebo/Grey</name>
            <uri>__default__</uri>
          </script>
        </material>
      </visual>
    </link>

    <joint name='fixed' type='revolute'>
      <child>base</child>
      <parent>world</parent>
         <axis>
        <limit>
          <lower>0</lower>
          <upper>0</upper>
        </limit>
        <dynamics>
          <damping>0</damping>
        </dynamics>
        <xyz>-1 0 0</xyz>
      </axis>
    </joint>

    <link name='L1'>
      <pose>0 0 0.571 -1.57079 -0 0</pose>
      
      <visual name='L1_visual'>   
        <geometry>
          <mesh>
            <scale>1 1 1</scale>
            <uri>/home/robotory/catkin_ws/src/downscale4/world/L1.dae</uri>
          </mesh>
        </geometry>
        <pose>0 0 0 1.57079 -0 0</pose>
        <material>
          <script>
            <name>Gazebo/Orange</name>
            <uri>__default__</uri>
          </script>
        </material>
      </visual>

      <collision name='L1_collision'>
        <geometry>
          <mesh>
            <scale>1 1 1</scale>
            <uri>/home/robotory/catkin_ws/src/downscale4/world/L1.dae</uri>
          </mesh>
        </geometry>
        <pose>0 0 0 1.57079 -0 0</pose>
      </collision>

      <inertial>
        <pose>0 0.04772 0.016252 0 -0 0</pose> <!--- Position of COM wrt base frame  -->
        <mass>23</mass>
        <inertia> <!-- inertia wrt COM  -->
          <ixx>0.2558</ixx>
          <ixy>0</ixy>
          <ixz>0</ixz>
          <iyy>0.1516</iyy>
          <iyz>0</iyz> <!--0.0478  -->
          <izz>0.1804</izz>
        </inertia>
      </inertial>
    </link>

    <joint name='J1' type='revolute'>
      <child>L1</child>
      <parent>base</parent>
      <axis>
        <xyz>0 0 1</xyz>
        <limit>
          <lower>-3.1415</lower><!-- -3.1415  -->
          <upper>3.1415</upper><!-- 3.1415  -->
        </limit>
        <dynamics>
          <damping>0</damping>
          <friction>10</friction>
        </dynamics>
      </axis>
	<sensor name="J1_sensor" type="force_torque">
          <update_rate>1000</update_rate>
        </sensor>
    </joint>



    <link name='L2'>
      <pose>0 0 0.571 0 -0 0</pose>

      <visual name='L2_visual'>
        <geometry>
          <mesh>
            <scale>1 1 1</scale>
            <uri>/home/robotory/catkin_ws/src/downscale4/world/L2.dae</uri>
          </mesh>
        </geometry>
        <pose>0 0 0 0 -0 0</pose>
        <material>
          <script>
            <name>Gazebo/Grey</name>
            <uri>__default__</uri>
          </script>
        </material>
      </visual>

      <collision name='L2_collision'>
        <geometry>
          <mesh>
            <scale>1 1 1</scale>
            <uri>/home/robotory/catkin_ws/src/downscale4/world/L2.dae</uri>
          </mesh>
        </geometry>
        <pose>0 0 0 0 -0 0</pose>
      </collision>

      <inertial>
        <pose>0 0 0.24043 0 -0 0</pose><!--- Position of COM wrt local link2 frame  -->
        <mass>16.5</mass>
        <inertia>
          <ixx>0.3159</ixx>
          <ixy>0</ixy>
          <ixz>0</ixz>
          <iyy>0.2535</iyy>
          <iyz>0.0071</iyz>
          <izz>0.0998</izz>
        </inertia>
      </inertial>
    </link>

    <joint name='J2' type='revolute'>
      <child>L2</child>
      <parent>L1</parent>
        <axis>
        <xyz>0 1 0</xyz>
        <limit>
          <lower>-2.26893</lower>
          <upper>2.26893</upper>
       </limit>
        <dynamics>
          <damping>0</damping>
          <friction>10</friction>
        </dynamics>
      </axis>
	<sensor name="J2_sensor" type="force_torque">
          <update_rate>1000</update_rate>
        </sensor>
    </joint>


    <link name='L3'>
      <pose>0 0 1.118 -1.57079 0 -0</pose>

      <visual name='L3_visual'>
        <geometry>
          <mesh>
            <scale>1 1 1</scale>
            <uri>/home/robotory/catkin_ws/src/downscale4/world/L3.dae</uri>
          </mesh>
        </geometry>
        <pose>0 0 0 1.57079 -0 0</pose>
        <material>
          <script>
            <name>Gazebo/Orange</name>
            <uri>__default__</uri>
          </script>
        </material>
      </visual>

      <collision name='L3_collision'>
        <geometry>
          <mesh>
            <scale>1 1 1</scale>
            <uri>/home/robotory/catkin_ws/src/downscale4/world/L3.dae</uri>
          </mesh>
        </geometry>
        <pose>0 0 0 1.57079 0 -0</pose>
      </collision>

      <inertial>
        <pose>0 0.02252 0.030685 0 -0 0</pose>
        <mass>25.5</mass>
        <inertia>
          <ixx>0.2164</ixx>
          <ixy>0</ixy>
          <ixz>0</ixz>
          <iyy>0.1129</iyy>
          <iyz>0</iyz>
          <izz>0.1605</izz>
        </inertia>
      </inertial>
    </link>

    <joint name='J3' type='revolute'>
      <child>L3</child>
      <parent>L2</parent>
      <axis>
        <xyz>0 0 1</xyz>
        <limit>
          <lower>-3.1415</lower><!-- -3.1415  -->
          <upper>3.1415</upper><!-- 3.1415  -->
          </limit>
        <dynamics>
          <damping>0</damping>
          <friction>10</friction>
        </dynamics>
      </axis>
	<sensor name="J3_sensor" type="force_torque">
          <update_rate>1000</update_rate>
        </sensor>
    </joint>


    <link name='L4'>
      <pose>0 0 1.118 0 0 -0</pose>

      <visual name='L4_visual'>
        <geometry>
          <mesh>
            <scale>1 1 1</scale>
            <uri>/home/robotory/catkin_ws/src/downscale4/world/L4.dae</uri>
          </mesh>
        </geometry>
        <pose>0 0 0 0 -0 0</pose>
        <material>
          <script>
            <name>Gazebo/Grey</name>
            <uri>__default__</uri>
          </script>
        </material>
      </visual>

      <collision name='L4_collision'>
        <geometry>
          <mesh>
            <scale>1 1 1</scale>
            <uri>/home/robotory/catkin_ws/src/downscale4/world/L4.dae</uri>
          </mesh>
        </geometry>
        <pose>0 0 0 0 -0 0</pose>
      </collision>

      <inertial>
        <pose>6.2e-05 0.001918 0.21711 0 -0 0</pose>
         <mass>6.4</mass>
        <inertia>
          <ixx>0.1221</ixx>
          <ixy>0</ixy>
          <ixz>0</ixz>
          <iyy>0.0997</iyy>
          <iyz>-0.0034</iyz>
          <izz>0.033</izz>
        </inertia>
      </inertial>
    </link>

    <joint name='J4' type='revolute'>
      <child>L4</child>
      <parent>L3</parent>
	<pose>0 0 0 0 0 0</pose>
      <axis>
        <xyz>-0 1 0</xyz>
        <limit>
          <lower>-2.26893</lower>
          <upper>2.26893</upper>
           </limit>
        <dynamics>
          <damping>0</damping>
          <friction>10</friction>
        </dynamics>
      </axis>
	<sensor name="J4_sensor" type="force_torque">
          <update_rate>1000</update_rate>
        </sensor>
    </joint>


    <link name='L5'>
      <pose>0 0 1.601 -1.57079 0 -0</pose> <!-- Z LENGTH: 1.601   -->

      <visual name='L5_visual'>
        <geometry>
          <mesh>
            <scale>1 1 1</scale>
            <uri>/home/robotory/catkin_ws/src/downscale4/world/L5.dae</uri>
          </mesh>
        </geometry>
        <pose>0 0 0 1.57079 0 -0</pose>
        <material>
          <script>
            <name>Gazebo/Orange</name>
            <uri>__default__</uri>
          </script>
        </material>
      </visual>

      <collision name='L5_collision'>
        <geometry>
          <mesh>
            <scale>1 1 1</scale>
            <uri>/home/robotory/catkin_ws/src/downscale4/world/L5.dae</uri>
          </mesh>
        </geometry>
        <pose>0 0 0 1.57079 0 -0</pose>
      </collision>

      <inertial>
        <pose>0 0.01779 0.024596 0 -0 3.14159</pose>
        <mass>6.74</mass>
        <inertia>
          <ixx>0.212</ixx><!--0.0293 -->
          <ixy>0.00</ixy>
          <ixz>0.0</ixz>
          <iyy>0.0168</iyy><!--0.0168 -->
          <iyz>0.00</iyz>
          <izz>0.0293</izz><!--0.212 -->
        </inertia>
      </inertial>
    </link>

    <joint name='J5' type='revolute'>
      <child>L5</child>
      <parent>L4</parent>
      <axis>
        <xyz>0 0 1</xyz>
        <limit>
          <lower>-3.1415</lower><!-- -3.1415  -->
          <upper>3.1415</upper><!-- 3.1415  -->
          </limit>
        <dynamics>
          <damping>0</damping>
          <friction>10</friction>
        </dynamics>
      </axis>
	<sensor name="J5_sensor" type="force_torque">
          <update_rate>1000</update_rate>
        </sensor>
    </joint>

    <link name='L6'>
      <pose>0 0 1.602 0 0 -0</pose>

      <visual name='L6_visual'>
        <geometry>
          <mesh>
            <scale>1 1 1</scale>
            <uri>/home/robotory/catkin_ws/src/downscale4/world/L6.dae</uri>
          </mesh>
        </geometry>
        <pose>0 0 0 0 -0 0</pose>
        <material>
          <script>
            <name>Gazebo/Grey</name>
            <uri>__default__</uri>
          </script>
        </material>
      </visual>

      <collision name='L6_collision'>
        <geometry>
          <mesh>
            <scale>1 1 1</scale>
            <uri>/home/robotory/catkin_ws/src/downscale4/world/L6.dae</uri>
          </mesh>
        </geometry>
        <pose>0 0 0 0 -0 0</pose>
      </collision>

      <inertial>
        <pose>0 0.001998 0.15735 0 -0 0</pose>
        <mass>3.9</mass>
        <inertia>
          <ixx>0.0415</ixx>
          <ixy>0</ixy>
          <ixz>0</ixz>
          <iyy>0.0331</iyy>
          <iyz>0</iyz>
          <izz>0.0141</izz>
        </inertia>
      </inertial>
    </link>
    <joint name='J6' type='revolute'>
      <child>L6</child>
      <parent>L5</parent>
      <axis>
        <xyz>0 1 0</xyz>
        <limit>
          <lower>-2.26893</lower>
          <upper>2.26893</upper>
          </limit>
        <dynamics>
          <damping>0</damping>
          <friction>10</friction>
        </dynamics>
      </axis>
	<sensor name="J6_sensor" type="force_torque">
          <update_rate>1000</update_rate>
        </sensor>
    </joint>


    <link name='L7'> <!-- weight test end eff-->
      <pose>0 0 1.84 1.5708 0 -1.5708</pose>

      <visual name='L7_visual'>
        <geometry>
          <mesh>
            <scale>1 1 1</scale>
            <uri>/home/robotory/catkin_ws/src/downscale4/world/L7_v1.STL</uri>
          </mesh>
        </geometry>
        <pose>0 0 0 0 -0 0</pose>
        <material>
          <script>
            <name>Gazebo/Orange</name>
            <uri>__default__</uri>
          </script>
        </material>
      </visual>

      <collision name='L7_collision'>
        <geometry>
          <mesh>
            <scale>1 1 1</scale>
            <uri>/home/robotory/catkin_ws/src/downscale4/world/L7_v1.STL</uri>
          </mesh>
        </geometry>
        <pose>0 0 0 0 -0 0</pose>
      </collision>

      <inertial>
        <pose>0 0 -0.02301 0 -0 0</pose>
        <mass>1</mass>
        <inertia>
          <ixx>0.0007</ixx>
          <ixy>0</ixy>
          <ixz>0</ixz>
          <iyy>0.0007</iyy>
          <iyz>0</iyz>
          <izz>0.0004</izz>
        </inertia>
      </inertial>
    </link>

    <joint name='J7' type='revolute'>
      <child>L7</child>
      <parent>L6</parent>
      <axis>
        <xyz>0 0 1</xyz>
        <limit>
          <lower>-3.1415</lower><!-- -3.1415  -->
          <upper>3.1415</upper><!-- 3.1415  -->
           </limit>
        <dynamics>
          <damping>0</damping>
          <friction>10</friction>
        </dynamics>
      </axis>
	<sensor name="J7_sensor" type="force_torque">
          <update_rate>1000</update_rate>
        </sensor>
    </joint>


<plugin name="ROSdownscalePlugin" filename="libsub_downscale.so"/>

  </model>
<!-- </physics> -->
</world>
</sdf>
